Workbook

Sheet Dashboard
A1: 2-Month Gym + Meal Plan — Boston / Northeastern
A2: Start date | B2: 46189 | C2: End date | D2: 46244 | E2: Current kg | F2: 67 | G2: Target kg | H2: 63
A4: Your Targets
A5: Height | B5: 1.67 m | C5: Plan length | D5: 8 weeks | E5: Goal | F5: Lose 4 kg while regaining muscle | G5: Main method | H5: Moderate deficit + progressive lifting
A6: Calories | B6: 1,900–2,050/day | C6: Protein | D6: 150–170 g/day | E6: Fat | F6: 50–60 g/day | G6: Carbs | H6: 180–230 g/day
A7: Training | B7: 5 days/week | C7: Cardio | D7: 3–5 sessions/week | E7: Steps | F7: 8,000–10,000/day | G7: Sleep | H7: 7–8 hours if possible
A8: Expected pace | B8: ~0.5 kg/week | C8: Check method | D8: 7-day average | E8: Adjustment | F8: Only change after 10–14 days | G8: Safety | H8: Stop if pain/dizziness
A10: 8-Week Overview
A11: Week | B11: Dates | C11: Target kg | D11: Training focus | E11: Cardio goal | F11: Nutrition focus | G11: Weekly check-in | H11: Notes
A12: 1 | B12: Jun 16–Jun 22 | C12: 66.5 | D12: Re-entry: technique + moderate volume | E12: 3 x 20–25 min incline walk | F12: Hit protein, learn portions | G12: Weigh 3–7x; use average | H12: Keep 2–3 reps in reserve
A13: 2 | B13: Jun 23–Jun 29 | C13: 66 | D13: Re-entry: technique + moderate volume | E13: 3 x 20–25 min incline walk | F13: Hit protein, learn portions | G13: Weigh 3–7x; use average | H13: Keep 2–3 reps in reserve
A14: 3 | B14: Jun 30–Jul 6 | C14: 65.5 | D14: Build: progressive overload | E14: 4 x 25–35 min | F14: Keep calories steady | G14: Weigh 3–7x; use average | H14: Add weight or reps weekly
A15: 4 | B15: Jul 7–Jul 13 | C15: 65 | D15: Build: progressive overload | E15: 4 x 25–35 min | F15: Keep calories steady | G15: Weigh 3–7x; use average | H15: Add weight or reps weekly
A16: 5 | B16: Jul 14–Jul 20 | C16: 64.5 | D16: Peak: strongest training weeks | E16: 4 x 30–40 min | F16: Tighten snacks/oil portions | G16: Weigh 3–7x; use average | H16: Last sets can reach RPE 8–9
A17: 6 | B17: Jul 21–Jul 27 | C17: 64 | D17: Peak: strongest training weeks | E17: 4 x 30–40 min | F17: Tighten snacks/oil portions | G17: Weigh 3–7x; use average | H17: Last sets can reach RPE 8–9
A18: 7 | B18: Jul 28–Aug 3 | C18: 63.5 | D18: Sharpen: maintain strength, slightly more cardio | E18: 4–5 x 35–45 min | F18: Strict weekdays, flexible 1 meal/week | G18: Weigh 3–7x; use average | H18: Do not crash diet
A19: 8 | B19: Aug 4–Aug 10 | C19: 63 | D19: Sharpen: maintain strength, slightly more cardio | E19: 4–5 x 35–45 min | F19: Strict weekdays, flexible 1 meal/week | G19: Weigh 3–7x; use average | H19: Do not crash diet
A22: Daily Non-Negotiables
A23: 1 | B23: Protein first: every meal should have a clear protein source.
A24: 2 | B24: Do not drink calories except protein shakes. Water, coffee, tea, zero-calorie drinks are fine.
A25: 3 | B25: Measure calorie-dense foods: oil, peanut butter, nuts, cheese, sauces.
A26: 4 | B26: Lift before long cardio when both are on the same day.
A27: 5 | B27: If you miss a day, do not punish yourself. Continue with the next scheduled workout.
A28: Daily Meal Timing — Based on 4:00 AM Wake-Up
A29: 4:00 AM | B29: Wake + water/coffee | C29: 8:30 AM | D29: Meal 1 / pre-workout breakfast | E29: 9:45–11:00 AM | F29: Gym | G29: 12:00 PM | H29: Meal 2 / post-workout lunch
A30: 3:30 PM | B30: Snack | C30: 7:00 PM | D30: Meal 3 / dinner | E30: 9:15–9:45 PM | F30: Sleep prep | G30: Optional | H30: Small protein snack only if protein is low
A31: Rule | B31: Pre-workout meal 60–120 min before lifting | C31: Rule | D31: Post-workout meal within 1–2h | E31: Rule | F31: Do not force food at 4 AM | G31: Rule | H31: Total calories/protein matter most
A33: If gym shifts later | B33: Breakfast 8:30; lunch 12:30; snack 60–90 min pre-gym; dinner after gym
A34: If very hungry at 4 AM | B34: Greek yogurt OR banana OR 1/2 scoop whey; keep under ~150 kcal
A35: See also | B35: Timing Guide sheet and Meal Calendar columns L:R

Sheet Gym Calendar
A1: 8-Week Gym Calendar
A2: Date | B2: Week | C2: Day | D2: Focus | E2: Workout Template | F2: Cardio | G2: Core/Mobility | H2: Intensity | I2: Notes
A3: 46189 | B3: 1 | C3: Tuesday | D3: Push | E3: Push A | F3: 20 min incline walk, 8–10% incline | G3: Shoulder warm-up | H3: RPE 6–7; leave 2–3 reps in reserve | I3: Chest/shoulders/triceps
A4: 46190 | B4: 1 | C4: Wednesday | D4: Pull | E4: Pull A | F4: Optional 15–20 min easy walk | G4: Upper-back mobility | H4: RPE 6–7; leave 2–3 reps in reserve | I4: Back/biceps/rear delts
A5: 46191 | B5: 1 | C5: Thursday | D5: Legs | E5: Legs A | F5: No hard cardio | G5: Core: plank + knee raises | H5: RPE 6–7; leave 2–3 reps in reserve | I5: Main leg strength day
A6: 46192 | B6: 1 | C6: Friday | D6: Upper | E6: Upper Mixed | F6: 20 min incline walk, 8–10% incline | G6: Band pull-aparts | H6: RPE 6–7; leave 2–3 reps in reserve | I6: Second upper-body stimulus
A7: 46193 | B7: 1 | C7: Saturday | D7: Lower + Core | E7: Lower B | F7: Optional 15 min easy walk | G7: Core circuit | H7: RPE 6–7; leave 2–3 reps in reserve | I7: Posterior chain + unilateral legs
A8: 46194 | B8: 1 | C8: Sunday | D8: Active Recovery | E8: Conditioning + Mobility | F8: Long walk 45–60 min (or easy bike); 8k–10k steps | G8: Full-body mobility | H8: RPE 6–7; leave 2–3 reps in reserve | I8: Longer walk + optional light arm pump; no heavy lifting
A9: 46195 | B9: 1 | C9: Monday | D9: Rest | E9: Recovery | F9: Walk outside; aim 8k–10k steps | G9: Stretch 10 min | H9: RPE 6–7; leave 2–3 reps in reserve | I9: No heavy lifting
A10: 46196 | B10: 2 | C10: Tuesday | D10: Push | E10: Push A | F10: 20 min incline walk, 8–10% incline | G10: Shoulder warm-up | H10: RPE 6–7; leave 2–3 reps in reserve | I10: Chest/shoulders/triceps
A11: 46197 | B11: 2 | C11: Wednesday | D11: Pull | E11: Pull A | F11: Optional 15–20 min easy walk | G11: Upper-back mobility | H11: RPE 6–7; leave 2–3 reps in reserve | I11: Back/biceps/rear delts
A12: 46198 | B12: 2 | C12: Thursday | D12: Legs | E12: Legs A | F12: No hard cardio | G12: Core: plank + knee raises | H12: RPE 6–7; leave 2–3 reps in reserve | I12: Main leg strength day
A13: 46199 | B13: 2 | C13: Friday | D13: Upper | E13: Upper Mixed | F13: 20 min incline walk, 8–10% incline | G13: Band pull-aparts | H13: RPE 6–7; leave 2–3 reps in reserve | I13: Second upper-body stimulus
A14: 46200 | B14: 2 | C14: Saturday | D14: Lower + Core | E14: Lower B | F14: Optional 15 min easy walk | G14: Core circuit | H14: RPE 6–7; leave 2–3 reps in reserve | I14: Posterior chain + unilateral legs
... A58: 46244 | B58: 8 | C58: Monday | D58: Rest | E58: Recovery | F58: Walk outside; aim 8k–10k steps | G58: Stretch 10 min | H58: Maintain weights; do not chase failure | I58: No heavy lifting

Sheet Workout Details
A1: Workout Details + 8-Week Progression
A2: Template | B2: Order | C2: Exercise | D2: Weeks 1–2 | E2: Weeks 3–4 | F2: Weeks 5–6 | G2: Weeks 7–8 | H2: Rest | I2: Technique cue | J2: Substitute if busy
A3: Push A | B3: 1 | C3: Barbell or DB Bench Press | D3: 3 x 8 @ RPE 6–7 | E3: 4 x 6–8 @ RPE 7–8 | F3: 4 x 6–8 @ RPE 8 | G3: 3 x 6–8, same weight if possible | H3: 2–3 min | I3: Control the lowering; no bouncing | J3: Chest press machine
A4: Push A | B4: 2 | C4: Incline DB Press | D4: 3 x 10 | E4: 3–4 x 8–10 | F4: 4 x 8–10 | G4: 3 x 8–10 | H4: 90 sec | I4: Elbows 30–45° from body | J4: Incline machine press
A5: Push A | B5: 3 | C5: Seated Shoulder Press | D5: 2–3 x 10 | E5: 3 x 8–10 | F5: 3–4 x 8 | G5: 3 x 8–10 | H5: 90 sec | I5: Do not over-arch lower back | J5: Machine shoulder press
A6: Push A | B6: 4 | C6: Cable or DB Lateral Raise | D6: 3 x 12–15 | E6: 3 x 12–15 | F6: 4 x 12–20 | G6: 3 x 15 | H6: 45–60 sec | I6: Lead with elbows; controlled reps | J6: Lateral raise machine
A7: Push A | B7: 5 | C7: Cable Fly or Pec Deck | D7: 2 x 12–15 | E7: 3 x 12–15 | F7: 3 x 12–15 | G7: 2–3 x 12–15 | H7: 60 sec | I7: Stretch chest without shoulder pain | J7: Push-ups
A8: Push A | B8: 6 | C8: Rope Triceps Pushdown | D8: 3 x 10–12 | E8: 3 x 10–15 | F8: 4 x 10–15 | G8: 3 x 12 | H8: 60 sec | I8: Lock elbows near ribs | J8: Straight-bar pushdown
A9: Push A | B9: 7 | C9: Overhead Cable Triceps Extension | D9: 2 x 12–15 | E9: 3 x 12–15 | F9: 3 x 12–15 | G9: 2 x 12–15 | H9: 60 sec | I9: Full stretch behind head | J9: DB overhead extension
A10: Pull A | B10: 1 | C10: Pull-up or Lat Pulldown | D10: 3 x 8–10 | E10: 4 x 8–10 | F10: 4 x 6–10 | G10: 3 x 8–10 | H10: 2 min | I10: Pull elbows down; avoid swinging | J10: Assisted pull-up
A11: Pull A | B11: 2 | C11: Chest-Supported Row | D11: 3 x 8–10 | E11: 4 x 8–10 | F11: 4 x 8 | G11: 3 x 8–10 | H11: 2 min | I11: Pause briefly at top | J11: Seated cable row
A12: Pull A | B12: 3 | C12: Seated Cable Row | D12: 3 x 10–12 | E12: 3 x 10–12 | F12: 4 x 10–12 | G12: 3 x 10–12 | H12: 90 sec | I12: Keep ribs down; squeeze back | J12: Machine row
A13: Pull A | B13: 4 | C13: Single-Arm Cable Pulldown | D13: 2 x 12/side | E13: 3 x 12/side | F13: 3 x 12–15/side | G13: 2–3 x 12/side | H13: 60 sec | I13: Reach and pull through elbow | J13: Straight-arm pulldown
A14: Pull A | B14: 5 | C14: Face Pull or Rear-Delt Fly | D14: 3 x 15 | E14: 3 x 15–20 | F14: 4 x 15–20 | G14: 3 x 15 | H14: 45–60 sec | I14: Move shoulders, not lower back | J14: Reverse pec deck
... A44: Arms (Optional / Sat) | B44: 7 | C44: Conditioning | D44: 25–30 min incline walk | E44: 35–40 min walk OR 8 intervals | F44: 40 min walk OR 10 intervals | G44: 40–45 min walk; avoid all-out sprints | H44: — | I44: Use cardio to support fat loss, not ruin recovery | J44: Bike/elliptical
A60: Progression Rules
A61: Rule | B61: What to do
A62: Double progression | B62: Use a weight you can do at the low end of the rep range. Add reps first. When you reach the top of the range on all sets, add 2.5–5 lb next time.
A63: RPE | B63: RPE 7 means about 3 reps left; RPE 8 means about 2 reps left; avoid true failure except occasional accessories.
A64: Rest | B64: Rest longer on compound lifts. Do not turn heavy sets into cardio.
A65: Warm-up | B65: 5–8 min easy cardio + 2–4 warm-up sets for the first big lift.
A66: Deload if needed | B66: If sleep is bad, joints hurt, or performance drops 2 sessions in a row, reduce accessories by 30% for 3–4 days.

Sheet Recipes Snacks
A1: Recipes, Snacks + Approximate Macros
A2: Meal Name | B2: Calories | C2: Protein g | D2: Type | E2: Ingredients | F2: How to make | G2: Best use | H2: Notes
A3: Protein Oatmeal | B3: 510 | C3: 35 | D3: Breakfast | E3: 1/2 cup oats; 1 scoop whey; 1 banana; 1 tbsp peanut butter; cinnamon | F3: Cook oats with water/milk, stir in whey after cooling slightly, add banana and peanut butter. | G3: Training days | H3: Easy dorm breakfast.
A4: Greek Yogurt Protein Bowl | B4: 500 | C4: 40 | D4: Breakfast | E4: 300g nonfat Greek yogurt; 40g oats/granola; berries; 1 tbsp peanut butter | F4: Mix yogurt + berries; add oats/granola and peanut butter. | G4: Any day | H4: Use less peanut butter if weight stalls.
A5: Egg Turkey Toast Plate | B5: 455 | C5: 46 | D5: Breakfast | E5: 2 eggs; 150g egg whites; 2 slices whole wheat toast; turkey slices; spinach/salsa | F5: Scramble eggs/egg whites with spinach; toast bread; add turkey slices. | G5: High-protein morning | H5: Good when appetite is high.
A6: Chicken Rice Bowl | B6: 625 | C6: 57 | D6: Lunch/Dinner | E6: 180g cooked chicken breast; 1 cup cooked rice; frozen vegetables; salsa; 1 tsp olive oil | F6: Cook chicken in bulk; microwave rice/veg; combine with salsa and measured oil. | G6: Meal prep staple | H6: Cheapest reliable main meal.
A7: Ground Turkey Pasta | B7: 640 | C7: 50 | D7: Lunch/Dinner | E7: 170g 93% ground turkey; 2 oz dry pasta; marinara; vegetables; parmesan optional | F7: Brown turkey; boil pasta; mix with marinara and vegetables. | G7: Post-workout dinner | H7: Keep pasta portion measured.
A8: Tuna Greek Yogurt Wrap | B8: 530 | C8: 42 | D8: Lunch/Dinner | E8: 1 large whole-wheat tortilla; 1 tuna can; Greek yogurt; pickles/cucumber; lettuce; fruit | F8: Mix tuna with Greek yogurt and seasoning; wrap with vegetables; add fruit. | G8: Quick lunch | H8: Cheap and no heavy cooking.
A9: Salmon Potato Plate | B9: 660 | C9: 46 | D9: Lunch/Dinner | E9: 5 oz salmon/fish; 300g potatoes; broccoli; 1 tsp olive oil | F9: Bake or pan-cook salmon; boil/air-fry potatoes; steam broccoli. | G9: 1–2x/week | H9: More expensive but great nutrition.
A10: Lean Beef Potato Bowl | B10: 630 | C10: 45 | D10: Lunch/Dinner | E10: 170g lean beef; 300g potatoes; peppers/onions; Greek-yogurt sauce | F10: Cook beef with vegetables; serve over potatoes; add yogurt sauce. | G10: Leg days | H10: Use turkey if beef is expensive.
A11: Chicken Salad Wrap | B11: 560 | C11: 50 | D11: Lunch/Dinner | E11: 150g chicken; salad kit or spinach; whole-wheat wrap; Greek yogurt/salsa sauce | F11: Wrap chicken and salad; use Greek yogurt-based sauce. | G11: Light dinner | H11: Very convenient.
A12: Cottage Cheese Fruit Bowl | B12: 260 | C12: 28 | D12: Snack | E12: 1 cup cottage cheese; berries or apple; cinnamon | F12: Mix and eat cold. | G12: Evening snack | H12: High protein, low effort.
A13: Whey Shake + Banana | B13: 225 | C13: 25 | D13: Snack | E13: 1 scoop whey; water; 1 banana | F13: Shake whey with water; eat banana. | G13: Post-workout or busy day | H13: Most convenient protein.
A14: Greek Yogurt + Apple | B14: 220 | C14: 20 | D14: Snack | E14: 200g Greek yogurt; 1 apple | F14: Eat as snack. | G14: Between meals | H14: Good sweet craving control.
... A16: Protein Bar Emergency | B16: 200 | C16: 20 | D16: Snack | E16: Any bar around 180–220 kcal and 18–22g protein | F16: Use when you cannot cook. | G16: Travel/busy days | H16: Not daily if trying to save money.
A20: Macro Note
A21: Approximation | B21: Macros are estimates. Target packages and brand labels can vary. For weight loss, the most important tracking items are oil, peanut butter, nuts, cheese, sauces, pasta, rice, and bread.
A22: Source note | B22: For generic nutrition cross-checks: USDA FoodData Central — https://fdc.nal.usda.gov/

Sheet Meal Calendar
A1: 8-Week Meal Calendar | L1: Meal Timing Based on 4:00 AM Wake-Up
A2: Date | B2: Week | C2: Training Day | D2: Breakfast | E2: Lunch | F2: Dinner | G2: Snack 1 | H2: Snack 2 | I2: Approx Calories | J2: Protein g | K2: Notes | L2: Wake / Early Work | M2: Meal 1 Time | N2: Gym Window | O2: Meal 2 Time | P2: Snack Time | Q2: Meal 3 Time | R2: Timing Notes
A3: 46189 | B3: 1 | C3: Push | D3: Egg Turkey Toast Plate | E3: Chicken Rice Bowl | F3: Ground Turkey Pasta | G3: Greek Yogurt + Apple | I3: =IFERROR(XLOOKUP(D3,'Recipes Snacks'!$A$3:$A$16,'Recipes Snacks'!$B$3:$B$16),0)+IFERROR(XLOOKUP(E3,'Recipes Snacks'!$A$3:$A$16,'Recipes Snacks'!$B$3:$B$16),0)+IFERROR(XLOOKUP(F3,'Recipes Snacks'!$A$3:$A$16,'Recipes Snacks'!$B$3:$B$16),0)+IFERROR(XLOOKUP(G3,'Recipes Snacks'!$A$3:$A$16,'Recipes Snacks'!$B$3:$B$16),0)+IFERROR(XLOOKUP(H3,'Recipes Snacks'!$A$3:$A$16,'Recipes Snacks'!$B$3:$B$16),0) | J3: =IFERROR(XLOOKUP(D3,'Recipes Snacks'!$A$3:$A$16,'Recipes Snacks'!$C$3:$C$16),0)+IFERROR(XLOOKUP(E3,'Recipes Snacks'!$A$3:$A$16,'Recipes Snacks'!$C$3:$C$16),0)+IFERROR(XLOOKUP(F3,'Recipes Snacks'!$A$3:$A$16,'Recipes Snacks'!$C$3:$C$16),0)+IFERROR(XLOOKUP(G3,'Recipes Snacks'!$A$3:$A$16,'Recipes Snacks'!$C$3:$C$16),0)+IFERROR(XLOOKUP(H3,'Recipes Snacks'!$A$3:$A$16,'Recipes Snacks'!$C$3:$C$16),0) | K3: ≈1,940 kcal. Add fruit only if training energy is low. | L3: 4:00 AM wake; water + coffee/tea | M3: 8:30 AM pre-workout breakfast | N3: 9:45–11:00 AM | O3: 12:00 PM post-workout lunch | P3: 3:30 PM | Q3: 7:00 PM | R3: Best default: lift after work block, then eat lunch within 1–2 hours.
A4: 46190 | B4: 1 | C4: Pull | D4: Greek Yogurt Protein Bowl | E4: Tuna Greek Yogurt Wrap | F4: Chicken Rice Bowl | G4: Cottage Cheese Fruit Bowl | I4: =IFERROR(XLOOKUP(D4,'Recipes Snacks'!$A$3:$A$16,'Recipes Snacks'!$B$3:$B$16),0)+IFERROR(XLOOKUP(E4,'Recipes Snacks'!$A$3:$A$16,'Recipes Snacks'!$B$3:$B$16),0)+IFERROR(XLOOKUP(F4,'Recipes Snacks'!$A$3:$A$16,'Recipes Snacks'!$B$3:$B$16),0)+IFERROR(XLOOKUP(G4,'Recipes Snacks'!$A$3:$A$16,'Recipes Snacks'!$B$3:$B$16),0)+IFERROR(XLOOKUP(H4,'Recipes Snacks'!$A$3:$A$16,'Recipes Snacks'!$B$3:$B$16),0) | J4: =IFERROR(XLOOKUP(D4,'Recipes Snacks'!$A$3:$A$16,'Recipes Snacks'!$C$3:$C$16),0)+IFERROR(XLOOKUP(E4,'Recipes Snacks'!$A$3:$A$16,'Recipes Snacks'!$C$3:$C$16),0)+IFERROR(XLOOKUP(F4,'Recipes Snacks'!$A$3:$A$16,'Recipes Snacks'!$C$3:$C$16),0)+IFERROR(XLOOKUP(G4,'Recipes Snacks'!$A$3:$A$16,'Recipes Snacks'!$C$3:$C$16),0)+IFERROR(XLOOKUP(H4,'Recipes Snacks'!$A$3:$A$16,'Recipes Snacks'!$C$3:$C$16),0) | K4: ≈1,915 kcal. Good protein day. | L4: 4:00 AM wake; water + coffee/tea | M4: 8:30 AM pre-workout breakfast | N4: 9:45–11:00 AM | O4: 12:00 PM post-workout lunch | P4: 3:30 PM | Q4: 7:00 PM | R4: Best default: lift after work block, then eat lunch within 1–2 hours.
A5: 46191 | B5: 1 | C5: Legs | D5: Protein Oatmeal | E5: Chicken Rice Bowl | F5: Lean Beef Potato Bowl | G5: Whey Shake + Banana | I5: =IFERROR(XLOOKUP(D5,'Recipes Snacks'!$A$3:$A$16,'Recipes Snacks'!$B$3:$B$16),0)+IFERROR(XLOOKUP(E5,'Recipes Snacks'!$A$3:$A$16,'Recipes Snacks'!$B$3:$B$16),0)+IFERROR(XLOOKUP(F5,'Recipes Snacks'!$A$3:$A$16,'Recipes Snacks'!$B$3:$B$16),0)+IFERROR(XLOOKUP(G5,'Recipes Snacks'!$A$3:$A$16,'Recipes Snacks'!$B$3:$B$16),0)+IFERROR(XLOOKUP(H5,'Recipes Snacks'!$A$3:$A$16,'Recipes Snacks'!$B$3:$B$16),0) | J5: =IFERROR(XLOOKUP(D5,'Recipes Snacks'!$A$3:$A$16,'Recipes Snacks'!$C$3:$C$16),0)+IFERROR(XLOOKUP(E5,'Recipes Snacks'!$A$3:$A$16,'Recipes Snacks'!$C$3:$C$16),0)+IFERROR(XLOOKUP(F5,'Recipes Snacks'!$A$3:$A$16,'Recipes Snacks'!$C$3:$C$16),0)+IFERROR(XLOOKUP(G5,'Recipes Snacks'!$A$3:$A$16,'Recipes Snacks'!$C$3:$C$16),0)+IFERROR(XLOOKUP(H5,'Recipes Snacks'!$A$3:$A$16,'Recipes Snacks'!$C$3:$C$16),0) | K5: ≈1,990 kcal. Highest-carb leg day. | L5: 4:00 AM wake; water + coffee/tea | M5: 8:30 AM pre-workout breakfast | N5: 9:45–11:15 AM | O5: 12:15 PM post-workout lunch | P5: 3:45 PM | Q5: 7:00 PM | R5: Hard lower-body day: keep breakfast/lunch carbs; do not skip lunch.
A6: 46192 | B6: 1 | C6: Upper | D6: Egg Turkey Toast Plate | E6: Ground Turkey Pasta | F6: Chicken Salad Wrap | G6: Cottage Cheese Fruit Bowl | I6: =IFERROR(XLOOKUP(D6,'Recipes Snacks'!$A$3:$A$16,'Recipes Snacks'!$B$3:$B$16),0)+IFERROR(XLOOKUP(E6,'Recipes Snacks'!$A$3:$A$16,'Recipes Snacks'!$B$3:$B$16),0)+IFERROR(XLOOKUP(F6,'Recipes Snacks'!$A$3:$A$16,'Recipes Snacks'!$B$3:$B$16),0)+IFERROR(XLOOKUP(G6,'Recipes Snacks'!$A$3:$A$16,'Recipes Snacks'!$B$3:$B$16),0)+IFERROR(XLOOKUP(H6,'Recipes Snacks'!$A$3:$A$16,'Recipes Snacks'!$B$3:$B$16),0) | J6: =IFERROR(XLOOKUP(D6,'Recipes Snacks'!$A$3:$A$16,'Recipes Snacks'!$C$3:$C$16),0)+IFERROR(XLOOKUP(E6,'Recipes Snacks'!$A$3:$A$16,'Recipes Snacks'!$C$3:$C$16),0)+IFERROR(XLOOKUP(F6,'Recipes Snacks'!$A$3:$A$16,'Recipes Snacks'!$C$3:$C$16),0)+IFERROR(XLOOKUP(G6,'Recipes Snacks'!$A$3:$A$16,'Recipes Snacks'!$C$3:$C$16),0)+IFERROR(XLOOKUP(H6,'Recipes Snacks'!$A$3:$A$16,'Recipes Snacks'!$C$3:$C$16),0) | K6: ≈1,915 kcal. Good protein distribution. | L6: 4:00 AM wake; water + coffee/tea | M6: 8:30 AM pre-workout breakfast | N6: 9:45–11:00 AM | O6: 12:00 PM post-workout lunch | P6: 3:30 PM | Q6: 7:00 PM | R6: Best default: lift after work block, then eat lunch within 1–2 hours.
A7: 46193 | B7: 1 | C7: Lower + Core | D7: Greek Yogurt Protein Bowl | E7: Chicken Rice Bowl | F7: Salmon Potato Plate | G7: Greek Yogurt + Apple | I7: =IFERROR(XLOOKUP(D7,'Recipes Snacks'!$A$3:$A$16,'Recipes Snacks'!$B$3:$B$16),0)+IFERROR(XLOOKUP(E7,'Recipes Snacks'!$A$3:$A$16,'Recipes Snacks'!$B$3:$B$16),0)+IFERROR(XLOOKUP(F7,'Recipes Snacks'!$A$3:$A$16,'Recipes Snacks'!$B$3:$B$16),0)+IFERROR(XLOOKUP(G7,'Recipes Snacks'!$A$3:$A$16,'Recipes Snacks'!$B$3:$B$16),0)+IFERROR(XLOOKUP(H7,'Recipes Snacks'!$A$3:$A$16,'Recipes Snacks'!$B$3:$B$16),0) | J7: =IFERROR(XLOOKUP(D7,'Recipes Snacks'!$A$3:$A$16,'Recipes Snacks'!$C$3:$C$16),0)+IFERROR(XLOOKUP(E7,'Recipes Snacks'!$A$3:$A$16,'Recipes Snacks'!$C$3:$C$16),0)+IFERROR(XLOOKUP(F7,'Recipes Snacks'!$A$3:$A$16,'Recipes Snacks'!$C$3:$C$16),0)+IFERROR(XLOOKUP(G7,'Recipes Snacks'!$A$3:$A$16,'Recipes Snacks'!$C$3:$C$16),0)+IFERROR(XLOOKUP(H7,'Recipes Snacks'!$A$3:$A$16,'Recipes Snacks'!$C$3:$C$16),0) | K7: ≈2,005 kcal. Fish meal day. | L7: 4:00 AM wake; water + coffee/tea | M7: 8:30 AM pre-workout breakfast | N7: 9:45–11:15 AM | O7: 12:15 PM post-workout lunch | P7: 3:45 PM | Q7: 7:00 PM | R7: Hard lower-body day: keep breakfast/lunch carbs; do not skip lunch.
A8: 46194 | B8: 1 | C8: Active Recovery | D8: Protein Oatmeal | E8: Tuna Greek Yogurt Wrap | F8: Chicken Rice Bowl | G8: Protein Bar Emergency | H8: Apple | I8: =IFERROR(XLOOKUP(D8,'Recipes Snacks'!$A$3:$A$16,'Recipes Snacks'!$B$3:$B$16),0)+IFERROR(XLOOKUP(E8,'Recipes Snacks'!$A$3:$A$16,'Recipes Snacks'!$B$3:$B$16),0)+IFERROR(XLOOKUP(F8,'Recipes Snacks'!$A$3:$A$16,'Recipes Snacks'!$B$3:$B$16),0)+IFERROR(XLOOKUP(G8,'Recipes Snacks'!$A$3:$A$16,'Recipes Snacks'!$B$3:$B$16),0)+IFERROR(XLOOKUP(H8,'Recipes Snacks'!$A$3:$A$16,'Recipes Snacks'!$B$3:$B$16),0) | J8: =IFERROR(XLOOKUP(D8,'Recipes Snacks'!$A$3:$A$16,'Recipes Snacks'!$C$3:$C$16),0)+IFERROR(XLOOKUP(E8,'Recipes Snacks'!$A$3:$A$16,'Recipes Snacks'!$C$3:$C$16),0)+IFERROR(XLOOKUP(F8,'Recipes Snacks'!$A$3:$A$16,'Recipes Snacks'!$C$3:$C$16),0)+IFERROR(XLOOKUP(G8,'Recipes Snacks'!$A$3:$A$16,'Recipes Snacks'!$C$3:$C$16),0)+IFERROR(XLOOKUP(H8,'Recipes Snacks'!$A$3:$A$16,'Recipes Snacks'!$C$3:$C$16),0) | K8: –1,960 kcal active-recovery day. Apple added to clear the 1,900 floor. | L8: 4:00 AM wake; water + coffee/tea | M8: 8:30 AM | N8: Walk 45–60 min anytime | O8: 12:00 PM | P8: 3:30 PM | Q8: 7:00 PM | R8: Active recovery: long walk 45–60 min; eat meals as planned.
A9: 46195 | B9: 1 | C9: Rest | D9: Greek Yogurt Protein Bowl | E9: Chicken Salad Wrap | F9: Lean Beef Potato Bowl | G9: Boiled Eggs + Fruit | I9: =IFERROR(XLOOKUP(D9,'Recipes Snacks'!$A$3:$A$16,'Recipes Snacks'!$B$3:$B$16),0)+IFERROR(XLOOKUP(E9,'Recipes Snacks'!$A$3:$A$16,'Recipes Snacks'!$B$3:$B$16),0)+IFERROR(XLOOKUP(F9,'Recipes Snacks'!$A$3:$A$16,'Recipes Snacks'!$B$3:$B$16),0)+IFERROR(XLOOKUP(G9,'Recipes Snacks'!$A$3:$A$16,'Recipes Snacks'!$B$3:$B$16),0)+IFERROR(XLOOKUP(H9,'Recipes Snacks'!$A$3:$A$16,'Recipes Snacks'!$B$3:$B$16),0) | J9: =IFERROR(XLOOKUP(D9,'Recipes Snacks'!$A$3:$A$16,'Recipes Snacks'!$C$3:$C$16),0)+IFERROR(XLOOKUP(E9,'Recipes Snacks'!$A$3:$A$16,'Recipes Snacks'!$C$3:$C$16),0)+IFERROR(XLOOKUP(F9,'Recipes Snacks'!$A$3:$A$16,'Recipes Snacks'!$C$3:$C$16),0)+IFERROR(XLOOKUP(G9,'Recipes Snacks'!$A$3:$A$16,'Recipes Snacks'!$C$3:$C$16),0)+IFERROR(XLOOKUP(H9,'Recipes Snacks'!$A$3:$A$16,'Recipes Snacks'!$C$3:$C$16),0) | K9: ≈1,940 kcal. Slightly lower-carb rest day. | L9: 4:00 AM wake; water + coffee/tea | M9: 8:30 AM | N9: No gym; walk 30–60 min anytime | O9: 12:30 PM | P9: 3:30 PM | Q9: 7:00 PM | R9: Keep carbs slightly lower; hit protein; no need for pre/post-workout timing.
A10: 46196 | B10: 2 | C10: Push | D10: Egg Turkey Toast Plate | E10: Chicken Rice Bowl | F10: Ground Turkey Pasta | G10: Greek Yogurt + Apple | I10: =IFERROR(XLOOKUP(D10,'Recipes Snacks'!$A$3:$A$16,'Recipes Snacks'!$B$3:$B$16),0)+IFERROR(XLOOKUP(E10,'Recipes Snacks'!$A$3:$A$16,'Recipes Snacks'!$B$3:$B$16),0)+IFERROR(XLOOKUP(F10,'Recipes Snacks'!$A$3:$A$16,'Recipes Snacks'!$B$3:$B$16),0)+IFERROR(XLOOKUP(G10,'Recipes Snacks'!$A$3:$A$16,'Recipes Snacks'!$B$3:$B$16),0)+IFERROR(XLOOKUP(H10,'Recipes Snacks'!$A$3:$A$16,'Recipes Snacks'!$B$3:$B$16),0) | J10: =IFERROR(XLOOKUP(D10,'Recipes Snacks'!$A$3:$A$16,'Recipes Snacks'!$C$3:$C$16),0)+IFERROR(XLOOKUP(E10,'Recipes Snacks'!$A$3:$A$16,'Recipes Snacks'!$C$3:$C$16),0)+IFERROR(XLOOKUP(F10,'Recipes Snacks'!$A$3:$A$16,'Recipes Snacks'!$C$3:$C$16),0)+IFERROR(XLOOKUP(G10,'Recipes Snacks'!$A$3:$A$16,'Recipes Snacks'!$C$3:$C$16),0)+IFERROR(XLOOKUP(H10,'Recipes Snacks'!$A$3:$A$16,'Recipes Snacks'!$C$3:$C$16),0) | K10: ≈1,940 kcal. Add fruit only if training energy is low. | L10: 4:00 AM wake; water + coffee/tea | M10: 8:30 AM pre-workout breakfast | N10: 9:45–11:00 AM | O10: 12:00 PM post-workout lunch | P10: 3:30 PM | Q10: 7:00 PM | R10: Best default: lift after work block, then eat lunch within 1–2 hours.
A11: 46197 | B11: 2 | C11: Pull | D11: Greek Yogurt Protein Bowl | E11: Tuna Greek Yogurt Wrap | F11: Chicken Rice Bowl | G11: Cottage Cheese Fruit Bowl | I11: =IFERROR(XLOOKUP(D11,'Recipes Snacks'!$A$3:$A$16,'Recipes Snacks'!$B$3:$B$16),0)+IFERROR(XLOOKUP(E11,'Recipes Snacks'!$A$3:$A$16,'Recipes Snacks'!$B$3:$B$16),0)+IFERROR(XLOOKUP(F11,'Recipes Snacks'!$A$3:$A$16,'Recipes Snacks'!$B$3:$B$16),0)+IFERROR(XLOOKUP(G11,'Recipes Snacks'!$A$3:$A$16,'Recipes Snacks'!$B$3:$B$16),0)+IFERROR(XLOOKUP(H11,'Recipes Snacks'!$A$3:$A$16,'Recipes Snacks'!$B$3:$B$16),0) | J11: =IFERROR(XLOOKUP(D11,'Recipes Snacks'!$A$3:$A$16,'Recipes Snacks'!$C$3:$C$16),0)+IFERROR(XLOOKUP(E11,'Recipes Snacks'!$A$3:$A$16,'Recipes Snacks'!$C$3:$C$16),0)+IFERROR(XLOOKUP(F11,'Recipes Snacks'!$A$3:$A$16,'Recipes Snacks'!$C$3:$C$16),0)+IFERROR(XLOOKUP(G11,'Recipes Snacks'!$A$3:$A$16,'Recipes Snacks'!$C$3:$C$16),0)+IFERROR(XLOOKUP(H11,'Recipes Snacks'!$A$3:$A$16,'Recipes Snacks'!$C$3:$C$16),0) | K11: ≈1,915 kcal. Good protein day. | L11: 4:00 AM wake; water + coffee/tea | M11: 8:30 AM pre-workout breakfast | N11: 9:45–11:00 AM | O11: 12:00 PM post-workout lunch | P11: 3:30 PM | Q11: 7:00 PM | R11: Best default: lift after work block, then eat lunch within 1–2 hours.
A12: 46198 | B12: 2 | C12: Legs | D12: Protein Oatmeal | E12: Chicken Rice Bowl | F12: Lean Beef Potato Bowl | G12: Whey Shake + Banana | I12: =IFERROR(XLOOKUP(D12,'Recipes Snacks'!$A$3:$A$16,'Recipes Snacks'!$B$3:$B$16),0)+IFERROR(XLOOKUP(E12,'Recipes Snacks'!$A$3:$A$16,'Recipes Snacks'!$B$3:$B$16),0)+IFERROR(XLOOKUP(F12,'Recipes Snacks'!$A$3:$A$16,'Recipes Snacks'!$B$3:$B$16),0)+IFERROR(XLOOKUP(G12,'Recipes Snacks'!$A$3:$A$16,'Recipes Snacks'!$B$3:$B$16),0)+IFERROR(XLOOKUP(H12,'Recipes Snacks'!$A$3:$A$16,'Recipes Snacks'!$B$3:$B$16),0) | J12: =IFERROR(XLOOKUP(D12,'Recipes Snacks'!$A$3:$A$16,'Recipes Snacks'!$C$3:$C$16),0)+IFERROR(XLOOKUP(E12,'Recipes Snacks'!$A$3:$A$16,'Recipes Snacks'!$C$3:$C$16),0)+IFERROR(XLOOKUP(F12,'Recipes Snacks'!$A$3:$A$16,'Recipes Snacks'!$C$3:$C$16),0)+IFERROR(XLOOKUP(G12,'Recipes Snacks'!$A$3:$A$16,'Recipes Snacks'!$C$3:$C$16),0)+IFERROR(XLOOKUP(H12,'Recipes Snacks'!$A$3:$A$16,'Recipes Snacks'!$C$3:$C$16),0) | K12: ≈1,990 kcal. Highest-carb leg day. | L12: 4:00 AM wake; water + coffee/tea | M12: 8:30 AM pre-workout breakfast | N12: 9:45–11:15 AM | O12: 12:15 PM post-workout lunch | P12: 3:45 PM | Q12: 7:00 PM | R12: Hard lower-body day: keep breakfast/lunch carbs; do not skip lunch.
A13: 46199 | B13: 2 | C13: Upper | D13: Egg Turkey Toast Plate | E13: Ground Turkey Pasta | F13: Chicken Salad Wrap | G13: Cottage Cheese Fruit Bowl | I13: =IFERROR(XLOOKUP(D13,'Recipes Snacks'!$A$3:$A$16,'Recipes Snacks'!$B$3:$B$16),0)+IFERROR(XLOOKUP(E13,'Recipes Snacks'!$A$3:$A$16,'Recipes Snacks'!$B$3:$B$16),0)+IFERROR(XLOOKUP(F13,'Recipes Snacks'!$A$3:$A$16,'Recipes Snacks'!$B$3:$B$16),0)+IFERROR(XLOOKUP(G13,'Recipes Snacks'!$A$3:$A$16,'Recipes Snacks'!$B$3:$B$16),0)+IFERROR(XLOOKUP(H13,'Recipes Snacks'!$A$3:$A$16,'Recipes Snacks'!$B$3:$B$16),0) | J13: =IFERROR(XLOOKUP(D13,'Recipes Snacks'!$A$3:$A$16,'Recipes Snacks'!$C$3:$C$16),0)+IFERROR(XLOOKUP(E13,'Recipes Snacks'!$A$3:$A$16,'Recipes Snacks'!$C$3:$C$16),0)+IFERROR(XLOOKUP(F13,'Recipes Snacks'!$A$3:$A$16,'Recipes Snacks'!$C$3:$C$16),0)+IFERROR(XLOOKUP(G13,'Recipes Snacks'!$A$3:$A$16,'Recipes Snacks'!$C$3:$C$16),0)+IFERROR(XLOOKUP(H13,'Recipes Snacks'!$A$3:$A$16,'Recipes Snacks'!$C$3:$C$16),0) | K13: ≈1,915 kcal. Good protein distribution. | L13: 4:00 AM wake; water + coffee/tea | M13: 8:30 AM pre-workout breakfast | N13: 9:45–11:00 AM | O13: 12:00 PM post-workout lunch | P13: 3:30 PM | Q13: 7:00 PM | R13: Best default: lift after work block, then eat lunch within 1–2 hours.
A14: 46200 | B14: 2 | C14: Lower + Core | D14: Greek Yogurt Protein Bowl | E14: Chicken Rice Bowl | F14: Salmon Potato Plate | G14: Greek Yogurt + Apple | I14: =IFERROR(XLOOKUP(D14,'Recipes Snacks'!$A$3:$A$16,'Recipes Snacks'!$B$3:$B$16),0)+IFERROR(XLOOKUP(E14,'Recipes Snacks'!$A$3:$A$16,'Recipes Snacks'!$B$3:$B$16),0)+IFERROR(XLOOKUP(F14,'Recipes Snacks'!$A$3:$A$16,'Recipes Snacks'!$B$3:$B$16),0)+IFERROR(XLOOKUP(G14,'Recipes Snacks'!$A$3:$A$16,'Recipes Snacks'!$B$3:$B$16),0)+IFERROR(XLOOKUP(H14,'Recipes Snacks'!$A$3:$A$16,'Recipes Snacks'!$B$3:$B$16),0) | J14: =IFERROR(XLOOKUP(D14,'Recipes Snacks'!$A$3:$A$16,'Recipes Snacks'!$C$3:$C$16),0)+IFERROR(XLOOKUP(E14,'Recipes Snacks'!$A$3:$A$16,'Recipes Snacks'!$C$3:$C$16),0)+IFERROR(XLOOKUP(F14,'Recipes Snacks'!$A$3:$A$16,'Recipes Snacks'!$C$3:$C$16),0)+IFERROR(XLOOKUP(G14,'Recipes Snacks'!$A$3:$A$16,'Recipes Snacks'!$C$3:$C$16),0)+IFERROR(XLOOKUP(H14,'Recipes Snacks'!$A$3:$A$16,'Recipes Snacks'!$C$3:$C$16),0) | K14: ≈2,005 kcal. Fish meal day. | L14: 4:00 AM wake; water + coffee/tea | M14: 8:30 AM pre-workout breakfast | N14: 9:45–11:15 AM | O14: 12:15 PM post-workout lunch | P14: 3:45 PM | Q14: 7:00 PM | R14: Hard lower-body day: keep breakfast/lunch carbs; do not skip lunch.
A15: 46201 | B15: 2 | C15: Active Recovery | D15: Protein Oatmeal | E15: Tuna Greek Yogurt Wrap | F15: Chicken Rice Bowl | G15: Protein Bar Emergency | H15: Apple | I15: =IFERROR(XLOOKUP(D15,'Recipes Snacks'!$A$3:$A$16,'Recipes Snacks'!$B$3:$B$16),0)+IFERROR(XLOOKUP(E15,'Recipes Snacks'!$A$3:$A$16,'Recipes Snacks'!$B$3:$B$16),0)+IFERROR(XLOOKUP(F15,'Recipes Snacks'!$A$3:$A$16,'Recipes Snacks'!$B$3:$B$16),0)+IFERROR(XLOOKUP(G15,'Recipes Snacks'!$A$3:$A$16,'Recipes Snacks'!$B$3:$B$16),0)+IFERROR(XLOOKUP(H15,'Recipes Snacks'!$A$3:$A$16,'Recipes Snacks'!$B$3:$B$16),0) | J15: =IFERROR(XLOOKUP(D15,'Recipes Snacks'!$A$3:$A$16,'Recipes Snacks'!$C$3:$C$16),0)+IFERROR(XLOOKUP(E15,'Recipes Snacks'!$A$3:$A$16,'Recipes Snacks'!$C$3:$C$16),0)+IFERROR(XLOOKUP(F15,'Recipes Snacks'!$A$3:$A$16,'Recipes Snacks'!$C$3:$C$16),0)+IFERROR(XLOOKUP(G15,'Recipes Snacks'!$A$3:$A$16,'Recipes Snacks'!$C$3:$C$16),0)+IFERROR(XLOOKUP(H15,'Recipes Snacks'!$A$3:$A$16,'Recipes Snacks'!$C$3:$C$16),0) | K15: –1,960 kcal active-recovery day. Apple added to clear the 1,900 floor. | L15: 4:00 AM wake; water + coffee/tea | M15: 8:30 AM | N15: Walk 45–60 min anytime | O15: 12:00 PM | P15: 3:30 PM | Q15: 7:00 PM | R15: Active recovery: long walk 45–60 min; eat meals as planned.
A16: 46202 | B16: 2 | C16: Rest | D16: Greek Yogurt Protein Bowl | E16: Chicken Salad Wrap | F16: Lean Beef Potato Bowl | G16: Boiled Eggs + Fruit | I16: =IFERROR(XLOOKUP(D16,'Recipes Snacks'!$A$3:$A$16,'Recipes Snacks'!$B$3:$B$16),0)+IFERROR(XLOOKUP(E16,'Recipes Snacks'!$A$3:$A$16,'Recipes Snacks'!$B$3:$B$16),0)+IFERROR(XLOOKUP(F16,'Recipes Snacks'!$A$3:$A$16,'Recipes Snacks'!$B$3:$B$16),0)+IFERROR(XLOOKUP(G16,'Recipes Snacks'!$A$3:$A$16,'Recipes Snacks'!$B$3:$B$16),0)+IFERROR(XLOOKUP(H16,'Recipes Snacks'!$A$3:$A$16,'Recipes Snacks'!$B$3:$B$16),0) | J16: =IFERROR(XLOOKUP(D16,'Recipes Snacks'!$A$3:$A$16,'Recipes Snacks'!$C$3:$C$16),0)+IFERROR(XLOOKUP(E16,'Recipes Snacks'!$A$3:$A$16,'Recipes Snacks'!$C$3:$C$16),0)+IFERROR(XLOOKUP(F16,'Recipes Snacks'!$A$3:$A$16,'Recipes Snacks'!$C$3:$C$16),0)+IFERROR(XLOOKUP(G16,'Recipes Snacks'!$A$3:$A$16,'Recipes Snacks'!$C$3:$C$16),0)+IFERROR(XLOOKUP(H16,'Recipes Snacks'!$A$3:$A$16,'Recipes Snacks'!$C$3:$C$16),0) | K16: ≈1,940 kcal. Slightly lower-carb rest day. | L16: 4:00 AM wake; water + coffee/tea | M16: 8:30 AM | N16: No gym; walk 30–60 min anytime | O16: 12:30 PM | P16: 3:30 PM | Q16: 7:00 PM | R16: Keep carbs slightly lower; hit protein; no need for pre/post-workout timing.
A17: 46203 | B17: 3 | C17: Push | D17: Egg Turkey Toast Plate | E17: Chicken Rice Bowl | F17: Ground Turkey Pasta | G17: Greek Yogurt + Apple | I17: =IFERROR(XLOOKUP(D17,'Recipes Snacks'!$A$3:$A$16,'Recipes Snacks'!$B$3:$B$16),0)+IFERROR(XLOOKUP(E17,'Recipes Snacks'!$A$3:$A$16,'Recipes Snacks'!$B$3:$B$16),0)+IFERROR(XLOOKUP(F17,'Recipes Snacks'!$A$3:$A$16,'Recipes Snacks'!$B$3:$B$16),0)+IFERROR(XLOOKUP(G17,'Recipes Snacks'!$A$3:$A$16,'Recipes Snacks'!$B$3:$B$16),0)+IFERROR(XLOOKUP(H17,'Recipes Snacks'!$A$3:$A$16,'Recipes Snacks'!$B$3:$B$16),0) | J17: =IFERROR(XLOOKUP(D17,'Recipes Snacks'!$A$3:$A$16,'Recipes Snacks'!$C$3:$C$16),0)+IFERROR(XLOOKUP(E17,'Recipes Snacks'!$A$3:$A$16,'Recipes Snacks'!$C$3:$C$16),0)+IFERROR(XLOOKUP(F17,'Recipes Snacks'!$A$3:$A$16,'Recipes Snacks'!$C$3:$C$16),0)+IFERROR(XLOOKUP(G17,'Recipes Snacks'!$A$3:$A$16,'Recipes Snacks'!$C$3:$C$16),0)+IFERROR(XLOOKUP(H17,'Recipes Snacks'!$A$3:$A$16,'Recipes Snacks'!$C$3:$C$16),0) | K17: ≈1,940 kcal. Add fruit only if training energy is low. | L17: 4:00 AM wake; water + coffee/tea | M17: 8:30 AM pre-workout breakfast | N17: 9:45–11:00 AM | O17: 12:00 PM post-workout lunch | P17: 3:30 PM | Q17: 7:00 PM | R17: Best default: lift after work block, then eat lunch within 1–2 hours.
A18: 46204 | B18: 3 | C18: Pull | D18: Greek Yogurt Protein Bowl | E18: Tuna Greek Yogurt Wrap | F18: Chicken Rice Bowl | G18: Cottage Cheese Fruit Bowl | I18: =IFERROR(XLOOKUP(D18,'Recipes Snacks'!$A$3:$A$16,'Recipes Snacks'!$B$3:$B$16),0)+IFERROR(XLOOKUP(E18,'Recipes Snacks'!$A$3:$A$16,'Recipes Snacks'!$B$3:$B$16),0)+IFERROR(XLOOKUP(F18,'Recipes Snacks'!$A$3:$A$16,'Recipes Snacks'!$B$3:$B$16),0)+IFERROR(XLOOKUP(G18,'Recipes Snacks'!$A$3:$A$16,'Recipes Snacks'!$B$3:$B$16),0)+IFERROR(XLOOKUP(H18,'Recipes Snacks'!$A$3:$A$16,'Recipes Snacks'!$B$3:$B$16),0) | J18: =IFERROR(XLOOKUP(D18,'Recipes Snacks'!$A$3:$A$16,'Recipes Snacks'!$C$3:$C$16),0)+IFERROR(XLOOKUP(E18,'Recipes Snacks'!$A$3:$A$16,'Recipes Snacks'!$C$3:$C$16),0)+IFERROR(XLOOKUP(F18,'Recipes Snacks'!$A$3:$A$16,'Recipes Snacks'!$C$3:$C$16),0)+IFERROR(XLOOKUP(G18,'Recipes Snacks'!$A$3:$A$16,'Recipes Snacks'!$C$3:$C$16),0)+IFERROR(XLOOKUP(H18,'Recipes Snacks'!$A$3:$A$16,'Recipes Snacks'!$C$3:$C$16),0) | K18: ≈1,915 kcal. Good protein day. | L18: 4:00 AM wake; water + coffee/tea | M18: 8:30 AM pre-workout breakfast | N18: 9:45–11:00 AM | O18: 12:00 PM post-workout lunch | P18: 3:30 PM | Q18: 7:00 PM | R18: Best default: lift after work block, then eat lunch within 1–2 hours.
A19: 46205 | B19: 3 | C19: Legs | D19: Protein Oatmeal | E19: Chicken Rice Bowl | F19: Lean Beef Potato Bowl | G19: Whey Shake + Banana | I19: =IFERROR(XLOOKUP(D19,'Recipes Snacks'!$A$3:$A$16,'Recipes Snacks'!$B$3:$B$16),0)+IFERROR(XLOOKUP(E19,'Recipes Snacks'!$A$3:$A$16,'Recipes Snacks'!$B$3:$B$16),0)+IFERROR(XLOOKUP(F19,'Recipes Snacks'!$A$3:$A$16,'Recipes Snacks'!$B$3:$B$16),0)+IFERROR(XLOOKUP(G19,'Recipes Snacks'!$A$3:$A$16,'Recipes Snacks'!$B$3:$B$16),0)+IFERROR(XLOOKUP(H19,'Recipes Snacks'!$A$3:$A$16,'Recipes Snacks'!$B$3:$B$16),0) | J19: =IFERROR(XLOOKUP(D19,'Recipes Snacks'!$A$3:$A$16,'Recipes Snacks'!$C$3:$C$16),0)+IFERROR(XLOOKUP(E19,'Recipes Snacks'!$A$3:$A$16,'Recipes Snacks'!$C$3:$C$16),0)+IFERROR(XLOOKUP(F19,'Recipes Snacks'!$A$3:$A$16,'Recipes Snacks'!$C$3:$C$16),0)+IFERROR(XLOOKUP(G19,'Recipes Snacks'!$A$3:$A$16,'Recipes Snacks'!$C$3:$C$16),0)+IFERROR(XLOOKUP(H19,'Recipes Snacks'!$A$3:$A$16,'Recipes Snacks'!$C$3:$C$16),0) | K19: ≈1,990 kcal. Highest-carb leg day. | L19: 4:00 AM wake; water + coffee/tea | M19: 8:30 AM pre-workout breakfast | N19: 9:45–11:15 AM | O19: 12:15 PM post-workout lunch | P19: 3:45 PM | Q19: 7:00 PM | R19: Hard lower-body day: keep breakfast/lunch carbs; do not skip lunch.
A20: 46206 | B20: 3 | C20: Upper | D20: Egg Turkey Toast Plate | E20: Ground Turkey Pasta | F20: Chicken Salad Wrap | G20: Cottage Cheese Fruit Bowl | I20: =IFERROR(XLOOKUP(D20,'Recipes Snacks'!$A$3:$A$16,'Recipes Snacks'!$B$3:$B$16),0)+IFERROR(XLOOKUP(E20,'Recipes Snacks'!$A$3:$A$16,'Recipes Snacks'!$B$3:$B$16),0)+IFERROR(XLOOKUP(F20,'Recipes Snacks'!$A$3:$A$16,'Recipes Snacks'!$B$3:$B$16),0)+IFERROR(XLOOKUP(G20,'Recipes Snacks'!$A$3:$A$16,'Recipes Snacks'!$B$3:$B$16),0)+IFERROR(XLOOKUP(H20,'Recipes Snacks'!$A$3:$A$16,'Recipes Snacks'!$B$3:$B$16),0) | J20: =IFERROR(XLOOKUP(D20,'Recipes Snacks'!$A$3:$A$16,'Recipes Snacks'!$C$3:$C$16),0)+IFERROR(XLOOKUP(E20,'Recipes Snacks'!$A$3:$A$16,'Recipes Snacks'!$C$3:$C$16),0)+IFERROR(XLOOKUP(F20,'Recipes Snacks'!$A$3:$A$16,'Recipes Snacks'!$C$3:$C$16),0)+IFERROR(XLOOKUP(G20,'Recipes Snacks'!$A$3:$A$16,'Recipes Snacks'!$C$3:$C$16),0)+IFERROR(XLOOKUP(H20,'Recipes Snacks'!$A$3:$A$16,'Recipes Snacks'!$C$3:$C$16),0) | K20: ≈1,915 kcal. Good protein distribution. | L20: 4:00 AM wake; water + coffee/tea | M20: 8:30 AM pre-workout breakfast | N20: 9:45–11:00 AM | O20: 12:00 PM post-workout lunch | P20: 3:30 PM | Q20: 7:00 PM | R20: Best default: lift after work block, then eat lunch within 1–2 hours.
A21: 46207 | B21: 3 | C21: Lower + Core | D21: Greek Yogurt Protein Bowl | E21: Chicken Rice Bowl | F21: Salmon Potato Plate | G21: Greek Yogurt + Apple | I21: =IFERROR(XLOOKUP(D21,'Recipes Snacks'!$A$3:$A$16,'Recipes Snacks'!$B$3:$B$16),0)+IFERROR(XLOOKUP(E21,'Recipes Snacks'!$A$3:$A$16,'Recipes Snacks'!$B$3:$B$16),0)+IFERROR(XLOOKUP(F21,'Recipes Snacks'!$A$3:$A$16,'Recipes Snacks'!$B$3:$B$16),0)+IFERROR(XLOOKUP(G21,'Recipes Snacks'!$A$3:$A$16,'Recipes Snacks'!$B$3:$B$16),0)+IFERROR(XLOOKUP(H21,'Recipes Snacks'!$A$3:$A$16,'Recipes Snacks'!$B$3:$B$16),0) | J21: =IFERROR(XLOOKUP(D21,'Recipes Snacks'!$A$3:$A$16,'Recipes Snacks'!$C$3:$C$16),0)+IFERROR(XLOOKUP(E21,'Recipes Snacks'!$A$3:$A$16,'Recipes Snacks'!$C$3:$C$16),0)+IFERROR(XLOOKUP(F21,'Recipes Snacks'!$A$3:$A$16,'Recipes Snacks'!$C$3:$C$16),0)+IFERROR(XLOOKUP(G21,'Recipes Snacks'!$A$3:$A$16,'Recipes Snacks'!$C$3:$C$16),0)+IFERROR(XLOOKUP(H21,'Recipes Snacks'!$A$3:$A$16,'Recipes Snacks'!$C$3:$C$16),0) | K21: ≈2,005 kcal. Fish meal day. | L21: 4:00 AM wake; water + coffee/tea | M21: 8:30 AM pre-workout breakfast | N21: 9:45–11:15 AM | O21: 12:15 PM post-workout lunch | P21: 3:45 PM | Q21: 7:00 PM | R21: Hard lower-body day: keep breakfast/lunch carbs; do not skip lunch.
A22: 46208 | B22: 3 | C22: Active Recovery | D22: Protein Oatmeal | E22: Tuna Greek Yogurt Wrap | F22: Chicken Rice Bowl | G22: Protein Bar Emergency | H22: Apple | I22: =IFERROR(XLOOKUP(D22,'Recipes Snacks'!$A$3:$A$16,'Recipes Snacks'!$B$3:$B$16),0)+IFERROR(XLOOKUP(E22,'Recipes Snacks'!$A$3:$A$16,'Recipes Snacks'!$B$3:$B$16),0)+IFERROR(XLOOKUP(F22,'Recipes Snacks'!$A$3:$A$16,'Recipes Snacks'!$B$3:$B$16),0)+IFERROR(XLOOKUP(G22,'Recipes Snacks'!$A$3:$A$16,'Recipes Snacks'!$B$3:$B$16),0)+IFERROR(XLOOKUP(H22,'Recipes Snacks'!$A$3:$A$16,'Recipes Snacks'!$B$3:$B$16),0) | J22: =IFERROR(XLOOKUP(D22,'Recipes Snacks'!$A$3:$A$16,'Recipes Snacks'!$C$3:$C$16),0)+IFERROR(XLOOKUP(E22,'Recipes Snacks'!$A$3:$A$16,'Recipes Snacks'!$C$3:$C$16),0)+IFERROR(XLOOKUP(F22,'Recipes Snacks'!$A$3:$A$16,'Recipes Snacks'!$C$3:$C$16),0)+IFERROR(XLOOKUP(G22,'Recipes Snacks'!$A$3:$A$16,'Recipes Snacks'!$C$3:$C$16),0)+IFERROR(XLOOKUP(H22,'Recipes Snacks'!$A$3:$A$16,'Recipes Snacks'!$C$3:$C$16),0) | K22: –1,960 kcal active-recovery day. Apple added to clear the 1,900 floor. | L22: 4:00 AM wake; water + coffee/tea | M22: 8:30 AM | N22: Walk 45–60 min anytime | O22: 12:00 PM | P22: 3:30 PM | Q22: 7:00 PM | R22: Active recovery: long walk 45–60 min; eat meals as planned.
A23: 46209 | B23: 3 | C23: Rest | D23: Greek Yogurt Protein Bowl | E23: Chicken Salad Wrap | F23: Lean Beef Potato Bowl | G23: Boiled Eggs + Fruit | I23: =IFERROR(XLOOKUP(D23,'Recipes Snacks'!$A$3:$A$16,'Recipes Snacks'!$B$3:$B$16),0)+IFERROR(XLOOKUP(E23,'Recipes Snacks'!$A$3:$A$16,'Recipes Snacks'!$B$3:$B$16),0)+IFERROR(XLOOKUP(F23,'Recipes Snacks'!$A$3:$A$16,'Recipes Snacks'!$B$3:$B$16),0)+IFERROR(XLOOKUP(G23,'Recipes Snacks'!$A$3:$A$16,'Recipes Snacks'!$B$3:$B$16),0)+IFERROR(XLOOKUP(H23,'Recipes Snacks'!$A$3:$A$16,'Recipes Snacks'!$B$3:$B$16),0) | J23: =IFERROR(XLOOKUP(D23,'Recipes Snacks'!$A$3:$A$16,'Recipes Snacks'!$C$3:$C$16),0)+IFERROR(XLOOKUP(E23,'Recipes Snacks'!$A$3:$A$16,'Recipes Snacks'!$C$3:$C$16),0)+IFERROR(XLOOKUP(F23,'Recipes Snacks'!$A$3:$A$16,'Recipes Snacks'!$C$3:$C$16),0)+IFERROR(XLOOKUP(G23,'Recipes Snacks'!$A$3:$A$16,'Recipes Snacks'!$C$3:$C$16),0)+IFERROR(XLOOKUP(H23,'Recipes Snacks'!$A$3:$A$16,'Recipes Snacks'!$C$3:$C$16),0) | K23: ≈1,940 kcal. Slightly lower-carb rest day. | L23: 4:00 AM wake; water + coffee/tea | M23: 8:30 AM | N23: No gym; walk 30–60 min anytime | O23: 12:30 PM | P23: 3:30 PM | Q23: 7:00 PM | R23: Keep carbs slightly lower; hit protein; no need for pre/post-workout timing.
A24: 46210 | B24: 4 | C24: Push | D24: Egg Turkey Toast Plate | E24: Chicken Rice Bowl | F24: Ground Turkey Pasta | G24: Greek Yogurt + Apple | I24: =IFERROR(XLOOKUP(D24,'Recipes Snacks'!$A$3:$A$16,'Recipes Snacks'!$B$3:$B$16),0)+IFERROR(XLOOKUP(E24,'Recipes Snacks'!$A$3:$A$16,'Recipes Snacks'!$B$3:$B$16),0)+IFERROR(XLOOKUP(F24,'Recipes Snacks'!$A$3:$A$16,'Recipes Snacks'!$B$3:$B$16),0)+IFERROR(XLOOKUP(G24,'Recipes Snacks'!$A$3:$A$16,'Recipes Snacks'!$B$3:$B$16),0)+IFERROR(XLOOKUP(H24,'Recipes Snacks'!$A$3:$A$16,'Recipes Snacks'!$B$3:$B$16),0) | J24: =IFERROR(XLOOKUP(D24,'Recipes Snacks'!$A$3:$A$16,'Recipes Snacks'!$C$3:$C$16),0)+IFERROR(XLOOKUP(E24,'Recipes Snacks'!$A$3:$A$16,'Recipes Snacks'!$C$3:$C$16),0)+IFERROR(XLOOKUP(F24,'Recipes Snacks'!$A$3:$A$16,'Recipes Snacks'!$C$3:$C$16),0)+IFERROR(XLOOKUP(G24,'Recipes Snacks'!$A$3:$A$16,'Recipes Snacks'!$C$3:$C$16),0)+IFERROR(XLOOKUP(H24,'Recipes Snacks'!$A$3:$A$16,'Recipes Snacks'!$C$3:$C$16),0) | K24: ≈1,940 kcal. Add fruit only if training energy is low. | L24: 4:00 AM wake; water + coffee/tea | M24: 8:30 AM pre-workout breakfast | N24: 9:45–11:00 AM | O24: 12:00 PM post-workout lunch | P24: 3:30 PM | Q24: 7:00 PM | R24: Best default: lift after work block, then eat lunch within 1–2 hours.
A25: 46211 | B25: 4 | C25: Pull | D25: Greek Yogurt Protein Bowl | E25: Tuna Greek Yogurt Wrap | F25: Chicken Rice Bowl | G25: Cottage Cheese Fruit Bowl | I25: =IFERROR(XLOOKUP(D25,'Recipes Snacks'!$A$3:$A$16,'Recipes Snacks'!$B$3:$B$16),0)+IFERROR(XLOOKUP(E25,'Recipes Snacks'!$A$3:$A$16,'Recipes Snacks'!$B$3:$B$16),0)+IFERROR(XLOOKUP(F25,'Recipes Snacks'!$A$3:$A$16,'Recipes Snacks'!$B$3:$B$16),0)+IFERROR(XLOOKUP(G25,'Recipes Snacks'!$A$3:$A$16,'Recipes Snacks'!$B$3:$B$16),0)+IFERROR(XLOOKUP(H25,'Recipes Snacks'!$A$3:$A$16,'Recipes Snacks'!$B$3:$B$16),0) | J25: =IFERROR(XLOOKUP(D25,'Recipes Snacks'!$A$3:$A$16,'Recipes Snacks'!$C$3:$C$16),0)+IFERROR(XLOOKUP(E25,'Recipes Snacks'!$A$3:$A$16,'Recipes Snacks'!$C$3:$C$16),0)+IFERROR(XLOOKUP(F25,'Recipes Snacks'!$A$3:$A$16,'Recipes Snacks'!$C$3:$C$16),0)+IFERROR(XLOOKUP(G25,'Recipes Snacks'!$A$3:$A$16,'Recipes Snacks'!$C$3:$C$16),0)+IFERROR(XLOOKUP(H25,'Recipes Snacks'!$A$3:$A$16,'Recipes Snacks'!$C$3:$C$16),0) | K25: ≈1,915 kcal. Good protein day. | L25: 4:00 AM wake; water + coffee/tea | M25: 8:30 AM pre-workout breakfast | N25: 9:45–11:00 AM | O25: 12:00 PM post-workout lunch | P25: 3:30 PM | Q25: 7:00 PM | R25: Best default: lift after work block, then eat lunch within 1–2 hours.
A26: 46212 | B26: 4 | C26: Legs | D26: Protein Oatmeal | E26: Chicken Rice Bowl | F26: Lean Beef Potato Bowl | G26: Whey Shake + Banana | I26: =IFERROR(XLOOKUP(D26,'Recipes Snacks'!$A$3:$A$16,'Recipes Snacks'!$B$3:$B$16),0)+IFERROR(XLOOKUP(E26,'Recipes Snacks'!$A$3:$A$16,'Recipes Snacks'!$B$3:$B$16),0)+IFERROR(XLOOKUP(F26,'Recipes Snacks'!$A$3:$A$16,'Recipes Snacks'!$B$3:$B$16),0)+IFERROR(XLOOKUP(G26,'Recipes Snacks'!$A$3:$A$16,'Recipes Snacks'!$B$3:$B$16),0)+IFERROR(XLOOKUP(H26,'Recipes Snacks'!$A$3:$A$16,'Recipes Snacks'!$B$3:$B$16),0) | J26: =IFERROR(XLOOKUP(D26,'Recipes Snacks'!$A$3:$A$16,'Recipes Snacks'!$C$3:$C$16),0)+IFERROR(XLOOKUP(E26,'Recipes Snacks'!$A$3:$A$16,'Recipes Snacks'!$C$3:$C$16),0)+IFERROR(XLOOKUP(F26,'Recipes Snacks'!$A$3:$A$16,'Recipes Snacks'!$C$3:$C$16),0)+IFERROR(XLOOKUP(G26,'Recipes Snacks'!$A$3:$A$16,'Recipes Snacks'!$C$3:$C$16),0)+IFERROR(XLOOKUP(H26,'Recipes Snacks'!$A$3:$A$16,'Recipes Snacks'!$C$3:$C$16),0) | K26: ≈1,990 kcal. Highest-carb leg day. | L26: 4:00 AM wake; water + coffee/tea | M26: 8:30 AM pre-workout breakfast | N26: 9:45–11:15 AM | O26: 12:15 PM post-workout lunch | P26: 3:45 PM | Q26: 7:00 PM | R26: Hard lower-body day: keep breakfast/lunch carbs; do not skip lunch.
A27: 46213 | B27: 4 | C27: Upper | D27: Egg Turkey Toast Plate | E27: Ground Turkey Pasta | F27: Chicken Salad Wrap | G27: Cottage Cheese Fruit Bowl | I27: =IFERROR(XLOOKUP(D27,'Recipes Snacks'!$A$3:$A$16,'Recipes Snacks'!$B$3:$B$16),0)+IFERROR(XLOOKUP(E27,'Recipes Snacks'!$A$3:$A$16,'Recipes Snacks'!$B$3:$B$16),0)+IFERROR(XLOOKUP(F27,'Recipes Snacks'!$A$3:$A$16,'Recipes Snacks'!$B$3:$B$16),0)+IFERROR(XLOOKUP(G27,'Recipes Snacks'!$A$3:$A$16,'Recipes Snacks'!$B$3:$B$16),0)+IFERROR(XLOOKUP(H27,'Recipes Snacks'!$A$3:$A$16,'Recipes Snacks'!$B$3:$B$16),0) | J27: =IFERROR(XLOOKUP(D27,'Recipes Snacks'!$A$3:$A$16,'Recipes Snacks'!$C$3:$C$16),0)+IFERROR(XLOOKUP(E27,'Recipes Snacks'!$A$3:$A$16,'Recipes Snacks'!$C$3:$C$16),0)+IFERROR(XLOOKUP(F27,'Recipes Snacks'!$A$3:$A$16,'Recipes Snacks'!$C$3:$C$16),0)+IFERROR(XLOOKUP(G27,'Recipes Snacks'!$A$3:$A$16,'Recipes Snacks'!$C$3:$C$16),0)+IFERROR(XLOOKUP(H27,'Recipes Snacks'!$A$3:$A$16,'Recipes Snacks'!$C$3:$C$16),0) | K27: ≈1,915 kcal. Good protein distribution. | L27: 4:00 AM wake; water + coffee/tea | M27: 8:30 AM pre-workout breakfast | N27: 9:45–11:00 AM | O27: 12:00 PM post-workout lunch | P27: 3:30 PM | Q27: 7:00 PM | R27: Best default: lift after work block, then eat lunch within 1–2 hours.
A28: 46214 | B28: 4 | C28: Lower + Core | D28: Greek Yogurt Protein Bowl | E28: Chicken Rice Bowl | F28: Salmon Potato Plate | G28: Greek Yogurt + Apple | I28: =IFERROR(XLOOKUP(D28,'Recipes Snacks'!$A$3:$A$16,'Recipes Snacks'!$B$3:$B$16),0)+IFERROR(XLOOKUP(E28,'Recipes Snacks'!$A$3:$A$16,'Recipes Snacks'!$B$3:$B$16),0)+IFERROR(XLOOKUP(F28,'Recipes Snacks'!$A$3:$A$16,'Recipes Snacks'!$B$3:$B$16),0)+IFERROR(XLOOKUP(G28,'Recipes Snacks'!$A$3:$A$16,'Recipes Snacks'!$B$3:$B$16),0)+IFERROR(XLOOKUP(H28,'Recipes Snacks'!$A$3:$A$16,'Recipes Snacks'!$B$3:$B$16),0) | J28: =IFERROR(XLOOKUP(D28,'Recipes Snacks'!$A$3:$A$16,'Recipes Snacks'!$C$3:$C$16),0)+IFERROR(XLOOKUP(E28,'Recipes Snacks'!$A$3:$A$16,'Recipes Snacks'!$C$3:$C$16),0)+IFERROR(XLOOKUP(F28,'Recipes Snacks'!$A$3:$A$16,'Recipes Snacks'!$C$3:$C$16),0)+IFERROR(XLOOKUP(G28,'Recipes Snacks'!$A$3:$A$16,'Recipes Snacks'!$C$3:$C$16),0)+IFERROR(XLOOKUP(H28,'Recipes Snacks'!$A$3:$A$16,'Recipes Snacks'!$C$3:$C$16),0) | K28: ≈2,005 kcal. Fish meal day. | L28: 4:00 AM wake; water + coffee/tea | M28: 8:30 AM pre-workout breakfast | N28: 9:45–11:15 AM | O28: 12:15 PM post-workout lunch | P28: 3:45 PM | Q28: 7:00 PM | R28: Hard lower-body day: keep breakfast/lunch carbs; do not skip lunch.
A29: 46215 | B29: 4 | C29: Active Recovery | D29: Protein Oatmeal | E29: Tuna Greek Yogurt Wrap | F29: Chicken Rice Bowl | G29: Protein Bar Emergency | H29: Apple | I29: =IFERROR(XLOOKUP(D29,'Recipes Snacks'!$A$3:$A$16,'Recipes Snacks'!$B$3:$B$16),0)+IFERROR(XLOOKUP(E29,'Recipes Snacks'!$A$3:$A$16,'Recipes Snacks'!$B$3:$B$16),0)+IFERROR(XLOOKUP(F29,'Recipes Snacks'!$A$3:$A$16,'Recipes Snacks'!$B$3:$B$16),0)+IFERROR(XLOOKUP(G29,'Recipes Snacks'!$A$3:$A$16,'Recipes Snacks'!$B$3:$B$16),0)+IFERROR(XLOOKUP(H29,'Recipes Snacks'!$A$3:$A$16,'Recipes Snacks'!$B$3:$B$16),0) | J29: =IFERROR(XLOOKUP(D29,'Recipes Snacks'!$A$3:$A$16,'Recipes Snacks'!$C$3:$C$16),0)+IFERROR(XLOOKUP(E29,'Recipes Snacks'!$A$3:$A$16,'Recipes Snacks'!$C$3:$C$16),0)+IFERROR(XLOOKUP(F29,'Recipes Snacks'!$A$3:$A$16,'Recipes Snacks'!$C$3:$C$16),0)+IFERROR(XLOOKUP(G29,'Recipes Snacks'!$A$3:$A$16,'Recipes Snacks'!$C$3:$C$16),0)+IFERROR(XLOOKUP(H29,'Recipes Snacks'!$A$3:$A$16,'Recipes Snacks'!$C$3:$C$16),0) | K29: –1,960 kcal active-recovery day. Apple added to clear the 1,900 floor. | L29: 4:00 AM wake; water + coffee/tea | M29: 8:30 AM | N29: Walk 45–60 min anytime | O29: 12:00 PM | P29: 3:30 PM | Q29: 7:00 PM | R29: Active recovery: long walk 45–60 min; eat meals as planned.
A30: 46216 | B30: 4 | C30: Rest | D30: Greek Yogurt Protein Bowl | E30: Chicken Salad Wrap | F30: Lean Beef Potato Bowl | G30: Boiled Eggs + Fruit | I30: =IFERROR(XLOOKUP(D30,'Recipes Snacks'!$A$3:$A$16,'Recipes Snacks'!$B$3:$B$16),0)+IFERROR(XLOOKUP(E30,'Recipes Snacks'!$A$3:$A$16,'Recipes Snacks'!$B$3:$B$16),0)+IFERROR(XLOOKUP(F30,'Recipes Snacks'!$A$3:$A$16,'Recipes Snacks'!$B$3:$B$16),0)+IFERROR(XLOOKUP(G30,'Recipes Snacks'!$A$3:$A$16,'Recipes Snacks'!$B$3:$B$16),0)+IFERROR(XLOOKUP(H30,'Recipes Snacks'!$A$3:$A$16,'Recipes Snacks'!$B$3:$B$16),0) | J30: =IFERROR(XLOOKUP(D30,'Recipes Snacks'!$A$3:$A$16,'Recipes Snacks'!$C$3:$C$16),0)+IFERROR(XLOOKUP(E30,'Recipes Snacks'!$A$3:$A$16,'Recipes Snacks'!$C$3:$C$16),0)+IFERROR(XLOOKUP(F30,'Recipes Snacks'!$A$3:$A$16,'Recipes Snacks'!$C$3:$C$16),0)+IFERROR(XLOOKUP(G30,'Recipes Snacks'!$A$3:$A$16,'Recipes Snacks'!$C$3:$C$16),0)+IFERROR(XLOOKUP(H30,'Recipes Snacks'!$A$3:$A$16,'Recipes Snacks'!$C$3:$C$16),0) | K30: ≈1,940 kcal. Slightly lower-carb rest day. | L30: 4:00 AM wake; water + coffee/tea | M30: 8:30 AM | N30: No gym; walk 30–60 min anytime | O30: 12:30 PM | P30: 3:30 PM | Q30: 7:00 PM | R30: Keep carbs slightly lower; hit protein; no need for pre/post-workout timing.
A31: 46217 | B31: 5 | C31: Push | D31: Egg Turkey Toast Plate | E31: Chicken Rice Bowl | F31: Ground Turkey Pasta | G31: Greek Yogurt + Apple | I31: =IFERROR(XLOOKUP(D31,'Recipes Snacks'!$A$3:$A$16,'Recipes Snacks'!$B$3:$B$16),0)+IFERROR(XLOOKUP(E31,'Recipes Snacks'!$A$3:$A$16,'Recipes Snacks'!$B$3:$B$16),0)+IFERROR(XLOOKUP(F31,'Recipes Snacks'!$A$3:$A$16,'Recipes Snacks'!$B$3:$B$16),0)+IFERROR(XLOOKUP(G31,'Recipes Snacks'!$A$3:$A$16,'Recipes Snacks'!$B$3:$B$16),0)+IFERROR(XLOOKUP(H31,'Recipes Snacks'!$A$3:$A$16,'Recipes Snacks'!$B$3:$B$16),0) | J31: =IFERROR(XLOOKUP(D31,'Recipes Snacks'!$A$3:$A$16,'Recipes Snacks'!$C$3:$C$16),0)+IFERROR(XLOOKUP(E31,'Recipes Snacks'!$A$3:$A$16,'Recipes Snacks'!$C$3:$C$16),0)+IFERROR(XLOOKUP(F31,'Recipes Snacks'!$A$3:$A$16,'Recipes Snacks'!$C$3:$C$16),0)+IFERROR(XLOOKUP(G31,'Recipes Snacks'!$A$3:$A$16,'Recipes Snacks'!$C$3:$C$16),0)+IFERROR(XLOOKUP(H31,'Recipes Snacks'!$A$3:$A$16,'Recipes Snacks'!$C$3:$C$16),0) | K31: ≈1,940 kcal. Add fruit only if training energy is low. | L31: 4:00 AM wake; water + coffee/tea | M31: 8:30 AM pre-workout breakfast | N31: 9:45–11:00 AM | O31: 12:00 PM post-workout lunch | P31: 3:30 PM | Q31: 7:00 PM | R31: Best default: lift after work block, then eat lunch within 1–2 hours.
A32: 46218 | B32: 5 | C32: Pull | D32: Greek Yogurt Protein Bowl | E32: Tuna Greek Yogurt Wrap | F32: Chicken Rice Bowl | G32: Cottage Cheese Fruit Bowl | I32: =IFERROR(XLOOKUP(D32,'Recipes Snacks'!$A$3:$A$16,'Recipes Snacks'!$B$3:$B$16),0)+IFERROR(XLOOKUP(E32,'Recipes Snacks'!$A$3:$A$16,'Recipes Snacks'!$B$3:$B$16),0)+IFERROR(XLOOKUP(F32,'Recipes Snacks'!$A$3:$A$16,'Recipes Snacks'!$B$3:$B$16),0)+IFERROR(XLOOKUP(G32,'Recipes Snacks'!$A$3:$A$16,'Recipes Snacks'!$B$3:$B$16),0)+IFERROR(XLOOKUP(H32,'Recipes Snacks'!$A$3:$A$16,'Recipes Snacks'!$B$3:$B$16),0) | J32: =IFERROR(XLOOKUP(D32,'Recipes Snacks'!$A$3:$A$16,'Recipes Snacks'!$C$3:$C$16),0)+IFERROR(XLOOKUP(E32,'Recipes Snacks'!$A$3:$A$16,'Recipes Snacks'!$C$3:$C$16),0)+IFERROR(XLOOKUP(F32,'Recipes Snacks'!$A$3:$A$16,'Recipes Snacks'!$C$3:$C$16),0)+IFERROR(XLOOKUP(G32,'Recipes Snacks'!$A$3:$A$16,'Recipes Snacks'!$C$3:$C$16),0)+IFERROR(XLOOKUP(H32,'Recipes Snacks'!$A$3:$A$16,'Recipes Snacks'!$C$3:$C$16),0) | K32: ≈1,915 kcal. Good protein day. | L32: 4:00 AM wake; water + coffee/tea | M32: 8:30 AM pre-workout breakfast | N32: 9:45–11:00 AM | O32: 12:00 PM post-workout lunch | P32: 3:30 PM | Q32: 7:00 PM | R32: Best default: lift after work block, then eat lunch within 1–2 hours.
A33: 46219 | B33: 5 | C33: Legs | D33: Protein Oatmeal | E33: Chicken Rice Bowl | F33: Lean Beef Potato Bowl | G33: Whey Shake + Banana | I33: =IFERROR(XLOOKUP(D33,'Recipes Snacks'!$A$3:$A$16,'Recipes Snacks'!$B$3:$B$16),0)+IFERROR(XLOOKUP(E33,'Recipes Snacks'!$A$3:$A$16,'Recipes Snacks'!$B$3:$B$16),0)+IFERROR(XLOOKUP(F33,'Recipes Snacks'!$A$3:$A$16,'Recipes Snacks'!$B$3:$B$16),0)+IFERROR(XLOOKUP(G33,'Recipes Snacks'!$A$3:$A$16,'Recipes Snacks'!$B$3:$B$16),0)+IFERROR(XLOOKUP(H33,'Recipes Snacks'!$A$3:$A$16,'Recipes Snacks'!$B$3:$B$16),0) | J33: =IFERROR(XLOOKUP(D33,'Recipes Snacks'!$A$3:$A$16,'Recipes Snacks'!$C$3:$C$16),0)+IFERROR(XLOOKUP(E33,'Recipes Snacks'!$A$3:$A$16,'Recipes Snacks'!$C$3:$C$16),0)+IFERROR(XLOOKUP(F33,'Recipes Snacks'!$A$3:$A$16,'Recipes Snacks'!$C$3:$C$16),0)+IFERROR(XLOOKUP(G33,'Recipes Snacks'!$A$3:$A$16,'Recipes Snacks'!$C$3:$C$16),0)+IFERROR(XLOOKUP(H33,'Recipes Snacks'!$A$3:$A$16,'Recipes Snacks'!$C$3:$C$16),0) | K33: ≈1,990 kcal. Highest-carb leg day. | L33: 4:00 AM wake; water + coffee/tea | M33: 8:30 AM pre-workout breakfast | N33: 9:45–11:15 AM | O33: 12:15 PM post-workout lunch | P33: 3:45 PM | Q33: 7:00 PM | R33: Hard lower-body day: keep breakfast/lunch carbs; do not skip lunch.
A34: 46220 | B34: 5 | C34: Upper | D34: Egg Turkey Toast Plate | E34: Ground Turkey Pasta | F34: Chicken Salad Wrap | G34: Cottage Cheese Fruit Bowl | I34: =IFERROR(XLOOKUP(D34,'Recipes Snacks'!$A$3:$A$16,'Recipes Snacks'!$B$3:$B$16),0)+IFERROR(XLOOKUP(E34,'Recipes Snacks'!$A$3:$A$16,'Recipes Snacks'!$B$3:$B$16),0)+IFERROR(XLOOKUP(F34,'Recipes Snacks'!$A$3:$A$16,'Recipes Snacks'!$B$3:$B$16),0)+IFERROR(XLOOKUP(G34,'Recipes Snacks'!$A$3:$A$16,'Recipes Snacks'!$B$3:$B$16),0)+IFERROR(XLOOKUP(H34,'Recipes Snacks'!$A$3:$A$16,'Recipes Snacks'!$B$3:$B$16),0) | J34: =IFERROR(XLOOKUP(D34,'Recipes Snacks'!$A$3:$A$16,'Recipes Snacks'!$C$3:$C$16),0)+IFERROR(XLOOKUP(E34,'Recipes Snacks'!$A$3:$A$16,'Recipes Snacks'!$C$3:$C$16),0)+IFERROR(XLOOKUP(F34,'Recipes Snacks'!$A$3:$A$16,'Recipes Snacks'!$C$3:$C$16),0)+IFERROR(XLOOKUP(G34,'Recipes Snacks'!$A$3:$A$16,'Recipes Snacks'!$C$3:$C$16),0)+IFERROR(XLOOKUP(H34,'Recipes Snacks'!$A$3:$A$16,'Recipes Snacks'!$C$3:$C$16),0) | K34: ≈1,915 kcal. Good protein distribution. | L34: 4:00 AM wake; water + coffee/tea | M34: 8:30 AM pre-workout breakfast | N34: 9:45–11:00 AM | O34: 12:00 PM post-workout lunch | P34: 3:30 PM | Q34: 7:00 PM | R34: Best default: lift after work block, then eat lunch within 1–2 hours.
A35: 46221 | B35: 5 | C35: Lower + Core | D35: Greek Yogurt Protein Bowl | E35: Chicken Rice Bowl | F35: Salmon Potato Plate | G35: Greek Yogurt + Apple | I35: =IFERROR(XLOOKUP(D35,'Recipes Snacks'!$A$3:$A$16,'Recipes Snacks'!$B$3:$B$16),0)+IFERROR(XLOOKUP(E35,'Recipes Snacks'!$A$3:$A$16,'Recipes Snacks'!$B$3:$B$16),0)+IFERROR(XLOOKUP(F35,'Recipes Snacks'!$A$3:$A$16,'Recipes Snacks'!$B$3:$B$16),0)+IFERROR(XLOOKUP(G35,'Recipes Snacks'!$A$3:$A$16,'Recipes Snacks'!$B$3:$B$16),0)+IFERROR(XLOOKUP(H35,'Recipes Snacks'!$A$3:$A$16,'Recipes Snacks'!$B$3:$B$16),0) | J35: =IFERROR(XLOOKUP(D35,'Recipes Snacks'!$A$3:$A$16,'Recipes Snacks'!$C$3:$C$16),0)+IFERROR(XLOOKUP(E35,'Recipes Snacks'!$A$3:$A$16,'Recipes Snacks'!$C$3:$C$16),0)+IFERROR(XLOOKUP(F35,'Recipes Snacks'!$A$3:$A$16,'Recipes Snacks'!$C$3:$C$16),0)+IFERROR(XLOOKUP(G35,'Recipes Snacks'!$A$3:$A$16,'Recipes Snacks'!$C$3:$C$16),0)+IFERROR(XLOOKUP(H35,'Recipes Snacks'!$A$3:$A$16,'Recipes Snacks'!$C$3:$C$16),0) | K35: ≈2,005 kcal. Fish meal day. | L35: 4:00 AM wake; water + coffee/tea | M35: 8:30 AM pre-workout breakfast | N35: 9:45–11:15 AM | O35: 12:15 PM post-workout lunch | P35: 3:45 PM | Q35: 7:00 PM | R35: Hard lower-body day: keep breakfast/lunch carbs; do not skip lunch.
A36: 46222 | B36: 5 | C36: Active Recovery | D36: Protein Oatmeal | E36: Tuna Greek Yogurt Wrap | F36: Chicken Rice Bowl | G36: Protein Bar Emergency | H36: Apple | I36: =IFERROR(XLOOKUP(D36,'Recipes Snacks'!$A$3:$A$16,'Recipes Snacks'!$B$3:$B$16),0)+IFERROR(XLOOKUP(E36,'Recipes Snacks'!$A$3:$A$16,'Recipes Snacks'!$B$3:$B$16),0)+IFERROR(XLOOKUP(F36,'Recipes Snacks'!$A$3:$A$16,'Recipes Snacks'!$B$3:$B$16),0)+IFERROR(XLOOKUP(G36,'Recipes Snacks'!$A$3:$A$16,'Recipes Snacks'!$B$3:$B$16),0)+IFERROR(XLOOKUP(H36,'Recipes Snacks'!$A$3:$A$16,'Recipes Snacks'!$B$3:$B$16),0) | J36: =IFERROR(XLOOKUP(D36,'Recipes Snacks'!$A$3:$A$16,'Recipes Snacks'!$C$3:$C$16),0)+IFERROR(XLOOKUP(E36,'Recipes Snacks'!$A$3:$A$16,'Recipes Snacks'!$C$3:$C$16),0)+IFERROR(XLOOKUP(F36,'Recipes Snacks'!$A$3:$A$16,'Recipes Snacks'!$C$3:$C$16),0)+IFERROR(XLOOKUP(G36,'Recipes Snacks'!$A$3:$A$16,'Recipes Snacks'!$C$3:$C$16),0)+IFERROR(XLOOKUP(H36,'Recipes Snacks'!$A$3:$A$16,'Recipes Snacks'!$C$3:$C$16),0) | K36: –1,960 kcal active-recovery day. Apple added to clear the 1,900 floor. | L36: 4:00 AM wake; water + coffee/tea | M36: 8:30 AM | N36: Walk 45–60 min anytime | O36: 12:00 PM | P36: 3:30 PM | Q36: 7:00 PM | R36: Active recovery: long walk 45–60 min; eat meals as planned.
A37: 46223 | B37: 5 | C37: Rest | D37: Greek Yogurt Protein Bowl | E37: Chicken Salad Wrap | F37: Lean Beef Potato Bowl | G37: Boiled Eggs + Fruit | I37: =IFERROR(XLOOKUP(D37,'Recipes Snacks'!$A$3:$A$16,'Recipes Snacks'!$B$3:$B$16),0)+IFERROR(XLOOKUP(E37,'Recipes Snacks'!$A$3:$A$16,'Recipes Snacks'!$B$3:$B$16),0)+IFERROR(XLOOKUP(F37,'Recipes Snacks'!$A$3:$A$16,'Recipes Snacks'!$B$3:$B$16),0)+IFERROR(XLOOKUP(G37,'Recipes Snacks'!$A$3:$A$16,'Recipes Snacks'!$B$3:$B$16),0)+IFERROR(XLOOKUP(H37,'Recipes Snacks'!$A$3:$A$16,'Recipes Snacks'!$B$3:$B$16),0) | J37: =IFERROR(XLOOKUP(D37,'Recipes Snacks'!$A$3:$A$16,'Recipes Snacks'!$C$3:$C$16),0)+IFERROR(XLOOKUP(E37,'Recipes Snacks'!$A$3:$A$16,'Recipes Snacks'!$C$3:$C$16),0)+IFERROR(XLOOKUP(F37,'Recipes Snacks'!$A$3:$A$16,'Recipes Snacks'!$C$3:$C$16),0)+IFERROR(XLOOKUP(G37,'Recipes Snacks'!$A$3:$A$16,'Recipes Snacks'!$C$3:$C$16),0)+IFERROR(XLOOKUP(H37,'Recipes Snacks'!$A$3:$A$16,'Recipes Snacks'!$C$3:$C$16),0) | K37: ≈1,940 kcal. Slightly lower-carb rest day. | L37: 4:00 AM wake; water + coffee/tea | M37: 8:30 AM | N37: No gym; walk 30–60 min anytime | O37: 12:30 PM | P37: 3:30 PM | Q37: 7:00 PM | R37: Keep carbs slightly lower; hit protein; no need for pre/post-workout timing.
A38: 46224 | B38: 6 | C38: Push | D38: Egg Turkey Toast Plate | E38: Chicken Rice Bowl | F38: Ground Turkey Pasta | G38: Greek Yogurt + Apple | I38: =IFERROR(XLOOKUP(D38,'Recipes Snacks'!$A$3:$A$16,'Recipes Snacks'!$B$3:$B$16),0)+IFERROR(XLOOKUP(E38,'Recipes Snacks'!$A$3:$A$16,'Recipes Snacks'!$B$3:$B$16),0)+IFERROR(XLOOKUP(F38,'Recipes Snacks'!$A$3:$A$16,'Recipes Snacks'!$B$3:$B$16),0)+IFERROR(XLOOKUP(G38,'Recipes Snacks'!$A$3:$A$16,'Recipes Snacks'!$B$3:$B$16),0)+IFERROR(XLOOKUP(H38,'Recipes Snacks'!$A$3:$A$16,'Recipes Snacks'!$B$3:$B$16),0) | J38: =IFERROR(XLOOKUP(D38,'Recipes Snacks'!$A$3:$A$16,'Recipes Snacks'!$C$3:$C$16),0)+IFERROR(XLOOKUP(E38,'Recipes Snacks'!$A$3:$A$16,'Recipes Snacks'!$C$3:$C$16),0)+IFERROR(XLOOKUP(F38,'Recipes Snacks'!$A$3:$A$16,'Recipes Snacks'!$C$3:$C$16),0)+IFERROR(XLOOKUP(G38,'Recipes Snacks'!$A$3:$A$16,'Recipes Snacks'!$C$3:$C$16),0)+IFERROR(XLOOKUP(H38,'Recipes Snacks'!$A$3:$A$16,'Recipes Snacks'!$C$3:$C$16),0) | K38: ≈1,940 kcal. Add fruit only if training energy is low. | L38: 4:00 AM wake; water + coffee/tea | M38: 8:30 AM pre-workout breakfast | N38: 9:45–11:00 AM | O38: 12:00 PM post-workout lunch | P38: 3:30 PM | Q38: 7:00 PM | R38: Best default: lift after work block, then eat lunch within 1–2 hours.
